<?xml version="1.0"?>
<robot name="wheely_dan" xmlns:xacro="http://www.ros.org/wiki/xacro">
    
    <material name="white">
        <color rgba="1 1 1 1"/>
    </material>

    <material name="red">
        <color rgba="0.3 0 0 1"/>
    </material>

    <material name="orange">
        <color rgba="1 0.3 0.1 1"/>
    </material>

    <material name="blue">
        <color rgba="0 0 0.05 1"/>
    </material>

    <material name="grey">
        <color rgba="0.4 0.4 0.4 1"/>
    </material>

    <material name="dark_grey">
        <color rgba="0.2 0.2 0.2 1"/>
    </material>

    <material name="green">
        <color rgba="0.125 0.3 0 1"/>
    </material>

    <!-- ========= BASE ========= -->

    <link name="base_link">

    </link>

    <!-- ========= CHASSIS ========= -->

    <link name="chassis_link">
        <visual>
        <geometry>
            <mesh filename="file:///home/logicbomb/Projects/SLAM/wheely-dan/src/wd_description/meshes/chassis_link.stl" scale="0.001 0.001 0.001"/>
        </geometry>
        <material name="grey"/>
        </visual>

        <collision>
        <geometry>
            <mesh filename="file:///home/logicbomb/Projects/SLAM/wheely-dan/src/wd_description/meshes/chassis_link.stl" scale="0.001 0.001 0.001"/>
        </geometry>
        </collision>

        <inertial>
            <origin xyz="0.097 0.003 0.029" rpy="0 0 0"/>
            <mass value="1.227"/>
            <inertia 
            ixx="3.86E-03" ixy="0" ixz="0"
            iyy="6.37E-03" iyz="0"
            izz="8.57E-03"/>
        </inertial>
    </link>

    <joint name="chassis_joint" type="fixed">
        <parent link="base_link"/>
        <child link="chassis_link"/>
        <origin xyz="-0.035 0 0"/>
    </joint>  


    <!-- ========= JETSON ========= -->

    <link name="jetson_link">
        <visual>
        <geometry>
            <mesh filename="file:///home/logicbomb/Projects/SLAM/wheely-dan/src/wd_description/meshes/jetson_link.stl" scale="0.001 0.001 0.001"/>
        </geometry>
        <material name="dark_grey"/>
        </visual>

        <collision>
        <geometry>
            <mesh filename="file:///home/logicbomb/Projects/SLAM/wheely-dan/src/wd_description/meshes/jetson_link.stl" scale="0.001 0.001 0.001"/>
        </geometry>
        </collision>

        <inertial>
            <origin xyz="0 0 0.005" rpy="0 0 0"/>
            <mass value="0.182"/>
            <inertia 
            ixx="1.79E-04" ixy="0" ixz="0"
            iyy="1.43E-04" iyz="0"
            izz="2.85E-04"/>
        </inertial>     
    </link>

    <joint name="jetson_joint" type="fixed">
        <parent link="base_link"/>
        <child link="jetson_link"/>
        <origin xyz="0.12625 0 0.057"/>
    </joint>

    
    <!-- ========= BATTERY ========= -->

    <link name="battery_link">
        <visual>
        <geometry>
            <mesh filename="file:///home/logicbomb/Projects/SLAM/wheely-dan/src/wd_description/meshes/battery_link.stl" scale="0.001 0.001 0.001"/>
        </geometry>
        <material name="red"/>
        </visual>

        <collision>
        <geometry>
            <mesh filename="file:///home/logicbomb/Projects/SLAM/wheely-dan/src/wd_description/meshes/battery_link.stl" scale="0.001 0.001 0.001"/>
        </geometry>
        </collision>

        <inertial>
            <origin xyz="0 0 0.0115" rpy="0 0 0"/>
            <mass value="0.178"/>
            <inertia 
            ixx="1.71E-04" ixy="0" ixz="0"
            iyy="2.50E-05" iyz="0"
            izz="1.81E-04"/>
        </inertial> 
    </link>

    <joint name="battery_joint" type="fixed">
        <parent link="base_link"/>
        <child link="battery_link"/>
        <origin xyz="0.163 0 0.011"/>
    </joint>

    <!-- ========= PCB ========= -->

    <link name="pcb_link">
        <visual>
        <geometry>
            <mesh filename="file:///home/logicbomb/Projects/SLAM/wheely-dan/src/wd_description/meshes/pcb_link.stl" scale="0.001 0.001 0.001"/>
        </geometry>
        <material name="green"/>
        </visual>

        <collision>
        <geometry>
            <mesh filename="file:///home/logicbomb/Projects/SLAM/wheely-dan/src/wd_description/meshes/pcb_link.stl" scale="0.001 0.001 0.001"/>
        </geometry>
        </collision>

        <inertial>
            <origin xyz="0 0 0" rpy="0 0 0"/>
            <mass value="0.04"/>
            <inertia 
            ixx="2.41E-05" ixy="0" ixz="0"
            iyy="2.13E-05" iyz="0"
            izz="4.54E-05"/>
        </inertial>
    </link>

    <joint name="pcb_joint" type="fixed">
        <parent link="base_link"/>
        <child link="pcb_link"/>
        <origin xyz="0.005 0 0.065"/>
    </joint>


    <!-- ========= MOTOR DRIVER L ========= -->

    <link name="driver_left_link">
        <visual>
        <geometry>
            <mesh filename="file:///home/logicbomb/Projects/SLAM/wheely-dan/src/wd_description/meshes/driver_left_link.stl" scale="0.001 0.001 0.001"/>
        </geometry>
        <material name="grey"/>
        </visual>

        <collision>
        <geometry>
            <mesh filename="file:///home/logicbomb/Projects/SLAM/wheely-dan/src/wd_description/meshes/driver_left_link.stl" scale="0.001 0.001 0.001"/>
        </geometry>
        </collision>

        <inertial>
            <origin xyz="0 0 0" rpy="0 0 0"/>
            <mass value="0.02"/>
            <inertia 
            ixx="6.24E-06" ixy="0" ixz="0"
            iyy="1.86E-06" iyz="0"
            izz="8.02E-06"/>
        </inertial>
    </link>

    <joint name="driver_left_joint" type="fixed">
        <parent link="base_link"/>
        <child link="driver_left_link"/>
        <origin xyz="0.04576 0.03548 0.018"/>
    </joint>

    <!-- ========= MOTOR DRIVER R ========= -->

    <link name="driver_right_link">
        <visual>
        <geometry>
            <mesh filename="file:///home/logicbomb/Projects/SLAM/wheely-dan/src/wd_description/meshes/driver_right_link.stl" scale="0.001 0.001 0.001"/>
        </geometry>
        <material name="grey"/>
        </visual>

        <collision>
        <geometry>
            <mesh filename="file:///home/logicbomb/Projects/SLAM/wheely-dan/src/wd_description/meshes/driver_right_link.stl" scale="0.001 0.001 0.001"/>
        </geometry>
        </collision>

        <inertial>
            <origin xyz="0 0 0" rpy="0 0 0"/>
            <mass value="0.02"/>
            <inertia 
            ixx="6.24E-06" ixy="0" ixz="0"
            iyy="1.86E-06" iyz="0"
            izz="8.02E-06"/>
        </inertial>
    </link>

    <joint name="driver_right_joint" type="fixed">
        <parent link="base_link"/>
        <child link="driver_right_link"/>
        <origin xyz="0.04576 -0.03548 0.018"/>
    </joint>

    <!-- ========= LIDAR ========= -->

    <link name="lidar_link">
        <visual>
        <geometry>
            <mesh filename="file:///home/logicbomb/Projects/SLAM/wheely-dan/src/wd_description/meshes/lidar_link.stl" scale="0.001 0.001 0.001"/>
        </geometry>
        <material name="dark_grey"/>
        </visual>

        <collision>
        <geometry>
            <mesh filename="file:///home/logicbomb/Projects/SLAM/wheely-dan/src/wd_description/meshes/lidar_link.stl" scale="0.001 0.001 0.001"/>
        </geometry>
        </collision>

        <!-- done -->
        <inertial>
            <origin xyz="0 0 0.0275" rpy="0 0 0"/>
            <mass value="0.187"/>
            <inertia 
            ixx="1.23E-04" ixy="0" ixz="0"
            iyy="2.03E-04" iyz="0"
            izz="2.32E-04"/>
        </inertial>
    </link>

    <joint name="lidar_joint" type="fixed">
        <parent link="base_link"/>
        <child link="lidar_link"/>
        <origin xyz="0.006175 0 0.095"/>
    </joint>


    <!-- ========= WHEEL L ========= -->

    <link name="wheel_left_link">
        <visual>
        <geometry>
            <mesh filename="file:///home/logicbomb/Projects/SLAM/wheely-dan/src/wd_description/meshes/wheel_left_link.stl" scale="0.001 0.001 0.001"/>
        </geometry>
        <material name="blue"/>
        </visual>

        <collision>
        <geometry>
            <mesh filename="file:///home/logicbomb/Projects/SLAM/wheely-dan/src/wd_description/meshes/wheel_left_link.stl" scale="0.001 0.001 0.001"/>
        </geometry>
        </collision>

        <inertial>
            <origin xyz="0 0.003 0" rpy="0 0 0"/>
            <mass value="0.046"/>
            <inertia 
            ixx="1.45E-05" ixy="0" ixz="0"
            iyy="2.43E-05" iyz="0"
            izz="1.45E-05"/>
        </inertial>
    </link>

    <joint name="wheel_left_joint" type="continuous">
        <parent link="base_link"/>
        <child link="wheel_left_link"/>
        <origin xyz="0 0.098 0.0145"/>
        <axis xyz="0 1 0"/>
        <limit effort="0.05" velocity="10.0"/>
    </joint>

    <!-- ========= WHEEL R ========= -->

    <link name="wheel_right_link">
        <visual>
        <geometry>
            <mesh filename="file:///home/logicbomb/Projects/SLAM/wheely-dan/src/wd_description/meshes/wheel_right_link.stl" scale="0.001 0.001 0.001"/>
        </geometry>
        <material name="blue"/>
        </visual>

        <collision>
        <geometry>
            <mesh filename="file:///home/logicbomb/Projects/SLAM/wheely-dan/src/wd_description/meshes/wheel_right_link.stl" scale="0.001 0.001 0.001"/>
        </geometry>
        </collision>

        <inertial>
            <origin xyz="0 -0.003 0" rpy="0 0 0"/>
            <mass value="0.046"/>
            <inertia 
            ixx="1.45E-05" ixy="0" ixz="0"
            iyy="2.43E-05" iyz="0"
            izz="1.45E-05"/>
        </inertial>
    </link>

    <joint name="wheel_right_joint" type="continuous">
        <parent link="base_link"/>
        <child link="wheel_right_link"/>
        <origin xyz="0 -0.098 0.0145"/>
        <axis xyz="0 1 0"/>
        <limit effort="0.05" velocity="10.0"/>
    </joint>


    <!-- ========= CASTER L ========= -->

    <link name="caster_fork_left_link">
        <visual>
        <geometry>
            <mesh filename="file:///home/logicbomb/Projects/SLAM/wheely-dan/src/wd_description/meshes/caster_fork_link.stl" scale="0.001 0.001 0.001"/>
        </geometry>
        <material name="dark_grey"/>
        </visual>

        <collision>
        <geometry>
            <mesh filename="file:///home/logicbomb/Projects/SLAM/wheely-dan/src/wd_description/meshes/caster_fork_link.stl" scale="0.001 0.001 0.001"/>
        </geometry>
        </collision>

        <inertial>
            <origin xyz="0 0 -0.004" rpy="0 0 0"/>
            <mass value="0.01"/>
            <inertia 
            ixx="2.79E-07" ixy="0" ixz="0"
            iyy="2.79E-07" iyz="0"
            izz="4.51E-07"/>
        </inertial>
    </link>

    <joint name="caster_fork_left_joint" type="fixed">
        <parent link="base_link"/>
        <child link="caster_fork_left_link"/>
        <origin xyz="0.15675 0.05375 -0.0033"/>
    </joint>


    <link name="caster_wheel_left_link">
        <visual>
        <geometry>
            <mesh filename="file:///home/logicbomb/Projects/SLAM/wheely-dan/src/wd_description/meshes/caster_wheel_link.stl" scale="0.001 0.001 0.001"/>
        </geometry>
        <material name="dark_grey"/>
        </visual>

        <collision>
        <geometry>
            <mesh filename="file:///home/logicbomb/Projects/SLAM/wheely-dan/src/wd_description/meshes/caster_wheel_link.stl" scale="0.001 0.001 0.001"/>
        </geometry>
        </collision>

        <inertial>
            <origin xyz="0 0 0" rpy="0 0 0"/>
            <mass value="0.004"/>
            <inertia 
            ixx="6.30E-08" ixy="0" ixz="0"
            iyy="7.20E-08" iyz="0"
            izz="6.30E-08"/>
        </inertial>
    </link>

    <joint name="caster_wheel_left_joint" type="continuous">
        <parent link="caster_fork_left_link"/>
        <child link="caster_wheel_left_link"/>
        <origin xyz="-0.01 0 -0.0107"/>
        <axis xyz="0 1 0"/>
    </joint>

    <!-- ========= CASTER R ========= -->

    <link name="caster_fork_right_link">
        <visual>
        <geometry>
            <mesh filename="file:///home/logicbomb/Projects/SLAM/wheely-dan/src/wd_description/meshes/caster_fork_link.stl" scale="0.001 0.001 0.001"/>
        </geometry>
        <material name="dark_grey"/>
        </visual>

        <collision>
        <geometry>
            <mesh filename="file:///home/logicbomb/Projects/SLAM/wheely-dan/src/wd_description/meshes/caster_fork_link.stl" scale="0.001 0.001 0.001"/>
        </geometry>
        </collision>

        <inertial>
            <origin xyz="0 0 -0.004" rpy="0 0 0"/>
            <mass value="0.01"/>
            <inertia 
            ixx="2.79E-07" ixy="0" ixz="0"
            iyy="2.79E-07" iyz="0"
            izz="4.51E-07"/>
        </inertial>
    </link>

    <joint name="caster_fork_right_joint" type="fixed">
        <parent link="base_link"/>
        <child link="caster_fork_right_link"/>
        <origin xyz="0.15675 -0.05375 -0.0033"/>
    </joint>


    <link name="caster_wheel_right_link">
        <visual>
        <geometry>
            <mesh filename="file:///home/logicbomb/Projects/SLAM/wheely-dan/src/wd_description/meshes/caster_wheel_link.stl" scale="0.001 0.001 0.001"/>
        </geometry>
        <material name="dark_grey"/>
        </visual>

        <collision>
        <geometry>
            <mesh filename="file:///home/logicbomb/Projects/SLAM/wheely-dan/src/wd_description/meshes/caster_wheel_link.stl" scale="0.001 0.001 0.001"/>
        </geometry>
        </collision>

        <inertial>
            <origin xyz="0 0 0" rpy="0 0 0"/>
            <mass value="0.004"/>
            <inertia 
            ixx="6.30E-08" ixy="0" ixz="0"
            iyy="7.20E-08" iyz="0"
            izz="6.30E-08"/>
        </inertial>
    </link>

    <joint name="caster_wheel_right_joint" type="continuous">
        <parent link="caster_fork_right_link"/>
        <child link="caster_wheel_right_link"/>
        <origin xyz="-0.01 0 -0.0107"/>
        <axis xyz="0 1 0"/>
    </joint>

    <!-- ========= GAZEBO SETTINGS ========= -->

    <gazebo reference="caster_wheel_left_link">
        <mu1 value="0.0"/>
        <mu2 value="0.0"/>
    </gazebo>

    <gazebo reference="caster_wheel_right_link">
        <mu1 value="0.0"/>
        <mu2 value="0.0"/>
    </gazebo>

</robot>